# Error Object

一个Error对象主要的属性包括：name、message、stack

## name

表示error类型的名称.初始值为"Error"。name属性和message属性一起,通过调用Error.prototype.toString()方法,会作为最后异常信息的字符串表示.

```js
var e = new Error("Malformed input"); // e.name默认是"Error"
e.name = "ParseError";                // e.toString()会成为下面这样的字符串
throw e;                              // "ParseError: Malformed input"
```


## message 

人类可阅读的错误描述信息

## stack

stack即堆栈跟踪信息，记录了调用历史，可以以此了解哪些文件导致了该错误，stack的顶部也包含了错误信息


# 错误处理

## try catch

通常通过try catch处理特定类型的异常

```js
try {
    foo.bar();
} catch (e) {
  if (e instanceof EvalError) {
      alert(e.name + ": " + e.message);
  } else if (e instanceof RangeError) {
      alert(e.name + ": " + e.message);
  }
}
```

try catch不会导致运行中断
```js
const a = 5

try {
    console.log(b) 
} catch (err) {
    console.error(err) 
} finally {
    console.log('finally') // 可选的finally块
}

console.log(a) // 5
```

# 在异步中处理错误

在异步操作中处理错误极为重要

## callback

传统的异步方案更多的使用回调函数

```js
myAsyncFunc(someInput, (err, result) => {
    if(err) return console.error(err) 
    console.log(result)
})
```

## promise

promise的错误处理方便，可读性好，无需显示声明try块，catch方法会自动捕获promise执行中的异常

```js
Promise.resolve(1)
  .then(res => {
      console.log(res) // 1
      throw new Error('something went wrong')
      return Promise.resolve(2)
  })
  .then(res => {
      console.log(res) // 由于throw，不执行
  })
  .catch(err => {
      console.error(err) // Error: something went wrong
      return Promise.resolve(3)
  })
  .then(res => {
      console.log(res) // 3
  })
  .catch(err => {
      console.error(err) // 没有新的错误则不执行
  })
```

如果没有使用catch方法，执行中的错误会throw至外层方法，通常，浏览器可以捕获这些遗漏的错误信息

不过需要注意的是，如果catch了错误但不做相应的处理，这会导致错误信息被隐藏，并且中断调用链，在维护上这可能会带来巨大的问题

```js
Promise.resolve(1)
  .then(res => {
      throw new Error('something went wrong')
      return Promise.resolve(2)
  }).catch(err => {
    // 没有正确的处理，调用链中断，同时浏览器不会显示任何错误信息，难以定位问题
  })
  .then(res => {
    console.log(res) // catch块没有返回值 res === undefined
  })
```

## async await 

随着async await的应用，我们不得不重新启用try，这有似乎点麻烦

```js
;(async function() {
  try {
      await someFuncThatThrowsAnError()
  } catch (err) {
      console.error(err)
  }
  console.log('Easy!') // 正常执行
})()
```

不过，我们可以通过语法糖改善这种情况

```js
const to = async (promise) => {
  try {
    const res = await promise
    return [null, res]
  } catch (err) {
    return [err]
  }
}

;(async function() {
  const [err, res] = await to(someFuncThatThrowsAnError())
  if (err) {
    console.error(err)
  }
  console.log('Easy!')
})()
```

# 自定义错误类型

我们可以扩展Error对象来描述业务系统中可能出现的错误

比起直接抛出错误信息，这么做的好处在于我们可以在错误信息中记录完整的调用栈跟踪信息

为了获取调用堆栈信息，我们通常有两种方式

## 1. (new Error()).stack

直接创建或抛出Error，即可通过stack属性获取调用堆栈信息

## 2. Error.captureStackTrace(targetObject[, constructorOpt])

captureStackTrace方法将为targetObject对象添加一个.stack属性。
对该属性进行访问时，将以字符串的形式返回Error.captureStackTrace()语句被调用时的代码位置信息，即调用信息。

Error.captureStackTrace同时接受一个类型为function的可选参数constructorOpt。
当传递该参数时，调用栈中所有constructorOpt函数自身及其之上的信息都会在访问targetObject.stack时被忽略。
当需要对终端用户隐藏内部的技术细节时，constructorOpt参数会很有用。

Error.captureStackTrace并非ES标准，而是源于V8的Stack Trace API，在node和chrome环境下有一致的接口

这样我们便可以实现一个包含自定义信息的Error对象

```js
class CustomError extends Error {
  // 添加默认的错误码与状态码
  constructor(code = 'NONE', status = 500, ...params) {
    super(...params)

    if (Error.captureStackTrace) {
      // 可选，参数this.constructor隐藏了更上层的错误信息
      Error.captureStackTrace(this, this.constructor)
    } else {
      (new Error()).stack
    }

    this.code = code
    this.status = status
  }
}

throw new CustomError(
    'CITY_NOT_EXIST',
    400,
    '不存在的城市编码'
)
```

如此，我们构建了前后端统一的错误对象，并且可以对终端用户隐藏不必要的调用信息，前端可以方便的捕获并展示错误信息。

## 参考

[Handling Errors in JavaScript: The Definitive Guide](https://levelup.gitconnected.com/the-definite-guide-to-handling-errors-gracefully-in-javascript-58424d9c60e6)

[MDN Error](https://developer.mozilla.org/zh-CN/docs/Web/JavaScript/Reference/Global_Objects/Error)